Workbook

Sheet quick price
A1: Quick Price
A2: RPO | B2: Price
A3: ZR1X Coupe 3LZ | B3: {=XLOOKUP(A3, modelPricing!$B:$B, modelPricing!$C:$C, "0", 0)} -> 218395
A4: R8E T0E | B4: {=XLOOKUP(A4, PriceSchedule!$B:$B, PriceSchedule!$D:$D, "0", 0)} -> 2600
A5: 3F9 | B5: {=XLOOKUP(A5, PriceSchedule!$B:$B, PriceSchedule!$D:$D, "0", 0)} -> 495
A6: NGA | B6: {=XLOOKUP(A6, PriceSchedule!$B:$B, PriceSchedule!$D:$D, "0", 0)} -> 395
A7: PEF | B7: {=XLOOKUP(A7, PriceSchedule!$B:$B, PriceSchedule!$D:$D, "0", 0)} -> 475
A8: SBT | B8: {=XLOOKUP(A8, PriceSchedule!$B:$B, PriceSchedule!$D:$D, "0", 0)} -> 2350
A9: BAZ | B9: {=XLOOKUP(A9, PriceSchedule!$B:$B, PriceSchedule!$D:$D, "0", 0)} -> 595
A10: E60 | B10: {=XLOOKUP(A10, PriceSchedule!$B:$B, PriceSchedule!$D:$D, "0", 0)} -> 2595
A11: ETV | B11: {=XLOOKUP(A11, PriceSchedule!$B:$B, PriceSchedule!$D:$D, "0", 0)} -> 995
A12: FA6 | B12: {=XLOOKUP(A12, PriceSchedule!$B:$B, PriceSchedule!$D:$D, "0", 0)} -> 4995
A13: J6E | B13: {=XLOOKUP(A13, PriceSchedule!$B:$B, PriceSchedule!$D:$D, "0", 0)} -> 695
A14: ZYC | B14: {=XLOOKUP(A14, PriceSchedule!$B:$B, PriceSchedule!$D:$D, "0", 0)} -> 195
A15: SPY | B15: {=XLOOKUP(A15, PriceSchedule!$B:$B, PriceSchedule!$D:$D, "0", 0)} -> 295
A16: SOG | B16: {=XLOOKUP(A16, PriceSchedule!$B:$B, PriceSchedule!$D:$D, "0", 0)} -> 1495
B17: {=XLOOKUP(A17, PriceSchedule!$B:$B, PriceSchedule!$D:$D, "0", 0)} -> 0
B18: {=XLOOKUP(A18, PriceSchedule!$B:$B, PriceSchedule!$D:$D, "0", 0)} -> 0
B19: {=XLOOKUP(A19, PriceSchedule!$B:$B, PriceSchedule!$D:$D, "0", 0)} -> 0
B20: {=XLOOKUP(A20, PriceSchedule!$B:$B, PriceSchedule!$D:$D, "0", 0)} -> 0
B21: {=XLOOKUP(A21, PriceSchedule!$B:$B, PriceSchedule!$D:$D, "0", 0)} -> 0
B22: {=XLOOKUP(A22, PriceSchedule!$B:$B, PriceSchedule!$D:$D, "0", 0)} -> 0
B23: {=XLOOKUP(A23, PriceSchedule!$B:$B, PriceSchedule!$D:$D, "0", 0)} -> 0
B24: {=XLOOKUP(A24, PriceSchedule!$B:$B, PriceSchedule!$D:$D, "0", 0)} -> 0
B25: {=XLOOKUP(A25, PriceSchedule!$B:$B, PriceSchedule!$D:$D, "0", 0)} -> 0
B26: {=XLOOKUP(A26, PriceSchedule!$B:$B, PriceSchedule!$D:$D, "0", 0)} -> 0
B27: {=XLOOKUP(A27, PriceSchedule!$B:$B, PriceSchedule!$D:$D, "0", 0)} -> 0
B28: {=XLOOKUP(A28, PriceSchedule!$B:$B, PriceSchedule!$D:$D, "0", 0)} -> 0
A29: MSRP: | B29: =SUM(B3:B28) -> 236570

Sheet modelPricing
A1: Model | B1: Model Description | C1: List Price | D1: MSRP(c) | E1: New DFC | F1: New List | G1: R8E | H1: LAST YEAR $$$ Incl DFC | I1: $ DIFF | J1: Diff Stingray | K1: Diff ERAY | L1: Diff Z06 | M1: Diff ZR1 | N1: Diff ZR1X
A2: 1YC07 | B2: Stingray Coupe 1LT | C2: 71995 | D2: 70000 | E2: 2495 | F2: =D2+E2 -> 72495 | G2: 0 | H2: 70195 | I2: 1800 | K2: =C2-C8 -> -38600 | L2: =C2-C14 -> -47700 | M2: =C2-C20 -> -110400 | N2: =C2-C24 -> -135400
A3: 1YC07 | B3: Stingray Coupe 2LT | C3: 79095 | D3: 77100 | E3: 2495 | F3: =D3+E3 -> 79595 | G3: 0 | H3: 77295 | I3: 1800 | K3: =C3-C9 -> -37000 | L3: =C3-C15 -> -49500
A4: 1YC07 | B4: Stingray Coupe 3LT | C4: 83745 | D4: 81750 | E4: 2495 | F4: =D4+E4 -> 84245 | G4: 0 | H4: 81945 | I4: 1800 | K4: =C4-C10 -> -37800 | L4: =C4-C16 -> -49500 | M4: =C4-C21 -> -109650 | N4: =C4-C25 -> -134650
A5: 1YC67 | B5: Stingray Convertible 1LT | C5: 78995 | D5: 77000 | E5: 2495 | F5: =D5+E5 -> 79495 | G5: 0 | H5: 77195 | I5: 1800 | K5: =C5-C11 -> -38600 | L5: =C5-C17 -> -47700 | M5: =C5-C22 -> -113400 | N5: =C5-C26 -> -138400
A6: 1YC67 | B6: Stingray Convertible 2LT | C6: 86095 | D6: 84100 | E6: 2495 | F6: =D6+E6 -> 86595 | G6: 0 | H6: 84295 | I6: 1800 | K6: =C6-C12 -> -37000 | L6: =C6-C18 -> -49500
A7: 1YC67 | B7: Stingray Convertible 3LT | C7: 90745 | D7: 88750 | E7: 2495 | F7: =D7+E7 -> 91245 | G7: 0 | H7: 88945 | I7: 1800 | K7: =C7-C13 -> -37800 | L7: =C7-C19 -> -49500 | M7: =C7-C23 -> -112650 | N7: =C7-C27 -> -137650
A8: 1YG07 | B8: E-Ray Coupe 1LZ | C8: 110595 | D8: 108600 | E8: 2495 | F8: =D8+E8 -> 111095 | G8: 0 | H8: 108795 | I8: 1800 | J8: =C8-C2 -> 38600 | L8: =C8-C14 -> -9100
A9: 1YG07 | B9: E-Ray Coupe 2LZ | C9: 116095 | D9: 114100 | E9: 2495 | F9: =D9+E9 -> 116595 | G9: 0 | H9: 114295 | I9: 1800 | J9: =C9-C3 -> 37000 | L9: =C9-C15 -> -12500
A10: 1YG07 | B10: E-Ray Coupe 3LZ | C10: 121545 | D10: 119550 | E10: 2495 | F10: =D10+E10 -> 122045 | G10: 0 | H10: 119745 | I10: 1800 | J10: =C10-C4 -> 37800 | L10: =C10-C16 -> -11700
A11: 1YG67 | B11: E-Ray Convertible 1LZ | C11: 117595 | D11: 115600 | E11: 2495 | F11: =D11+E11 -> 118095 | G11: 0 | H11: 115795 | I11: 1800 | J11: =C11-C5 -> 38600 | L11: =C11-C17 -> -9100
A12: 1YG67 | B12: E-Ray Convertible 2LZ | C12: 123095 | D12: 121100 | E12: 2495 | F12: =D12+E12 -> 123595 | G12: 0 | H12: 121295 | I12: 1800 | J12: =C12-C6 -> 37000 | L12: =C12-C18 -> -12500
A13: 1YG67 | B13: E-Ray Convertible 3LZ | C13: 128545 | D13: 126550 | E13: 2495 | F13: =D13+E13 -> 129045 | G13: 0 | H13: 126745 | I13: 1800 | J13: =C13-C7 -> 37800 | L13: =C13-C19 -> -11700
A14: 1YH07 | B14: Z06 Coupe 1LZ | C14: 119695 | D14: 117700 | E14: 2495 | F14: =D14+E14 -> 120195 | H14: 113995 | I14: 5700 | J14: =C14-C2 -> 47700 | K14: =C14-C8 -> 9100
A15: 1YH07 | B15: Z06 Coupe 2LZ | C15: 128595 | D15: 126600 | E15: 2495 | F15: =D15+E15 -> 129095 | H15: 122895 | I15: 5700 | J15: =C15-C3 -> 49500 | K15: =C15-C9 -> 12500
A16: 1YH07 | B16: Z06 Coupe 3LZ | C16: 133245 | D16: 131250 | E16: 2495 | F16: =D16+E16 -> 133745 | H16: 127545 | I16: 5700 | J16: =C16-C4 -> 49500 | K16: =C16-C10 -> 11700
A17: 1YH67 | B17: Z06 Convertible 1LZ | C17: 126695 | D17: 124700 | E17: 2495 | F17: =D17+E17 -> 127195 | H17: 120995 | I17: 5700 | J17: =C17-C5 -> 47700 | K17: =C17-C11 -> 9100
A18: 1YH67 | B18: Z06 Convertible 2LZ | C18: 135595 | D18: 133600 | E18: 2495 | F18: =D18+E18 -> 136095 | H18: 129895 | I18: 5700 | J18: =C18-C6 -> 49500 | K18: =C18-C12 -> 12500
A19: 1YH67 | B19: Z06 Convertible 3LZ | C19: 140245 | D19: 138250 | E19: 2495 | F19: =D19+E19 -> 140745 | H19: 134545 | I19: 5700 | J19: =C19-C7 -> 49500 | K19: =C19-C13 -> 11700
A20: 1YR07 | B20: ZR1 Coupe 1LZ | C20: 182395 | D20: 180400 | E20: 2495 | F20: =D20+E20 -> 182895 | H20: 175195 | I20: 7200 | J20: =C20-C2 -> 110400 | K20: =C20-C8 -> 71800
A21: 1YR07 | B21: ZR1 Coupe 3LZ | C21: 193395 | D21: 191400 | E21: 2495 | F21: =D21+E21 -> 193895 | H21: 186195 | I21: 7200 | J21: =C21-C4 -> 109650 | K21: =C21-C10 -> 71850
A22: 1YR67 | B22: ZR1 Convertible 1LZ | C22: 192395 | D22: 190400 | E22: 2495 | F22: =D22+E22 -> 192895 | H22: 185195 | I22: 7200 | J22: =C22-C5 -> 113400 | K22: =C22-C11 -> 74800
A23: 1YR67 | B23: ZR1 Convertible 3LZ | C23: 203395 | D23: 201400 | E23: 2495 | F23: =D23+E23 -> 203895 | H23: 196195 | I23: 7200 | J23: =C23-C7 -> 112650 | K23: =C23-C13 -> 74850
A24: 1YS07 | B24: ZR1X Coupe 1LZ | C24: 207395 | D24: 207100 | E24: 2495 | F24: =D24+E24 -> 209595 | J24: =C24-C2 -> 135400 | K24: =C24-C8 -> 96800
A25: 1YS07 | B25: ZR1X Coupe 3LZ | C25: 218395 | D25: 218100 | E25: 2495 | F25: =D25+E25 -> 220595 | J25: =C25-C4 -> 134650 | K25: =C25-C10 -> 96850
A26: 1YS67 | B26: ZR1X Convertible 1LZ | C26: 217395 | D26: 217100 | E26: 2495 | F26: =D26+E26 -> 219595 | J26: =C26-C5 -> 138400 | K26: =C26-C11 -> 99800
A27: 1YS67 | B27: ZR1X Convertible 3LZ | C27: 228395 | D27: 228100 | E27: 2495 | F27: =D27+E27 -> 230595 | J27: =C27-C7 -> 137650 | K27: =C27-C13 -> 99850

Sheet STINGRAY
A1: RPO Code | B1: Name | C1: Price | D1: Detail | E1: Compatibility | F1: Category | G1: Section | H1: Column 8
A2: 5DG | B2: 20-Spoke Tech Bronze Forged Aluminum Rims | C2: 3650 | D2: Comes as a Second Set of Wheels. Includes Bronze center caps, Black wheel locks and Black Lugnuts | E2: Not available w/ R8C | F2: lpo, wheels | G2: Exterior Accessories | H2: {=UNIQUE(G2:G133)} -> Exterior Accessories
A3: 5DO | B3: 15-spoke Bright polished aluminum wheels | C3: 4695 | D3: Comes as a 2nd set of wheels | E3: Not available w/ R8C | F3: lpo, wheels | G3: Exterior Accessories | H3: Carbon Fiber
A4: 5JR | B4: Visible Carbon Fiber Mirror Covers | C4: 1250 | D4: 3LT/LZ only. Adds DRG carbon flash painted mirrors (N/C) | E4: 3LT/LZ only. Available with 1LZ on ZR1. | F4: carbon_fiber, lpo | G4: Carbon Fiber | H4: Spoilers
A5: 5V5 | B5: High Wing Spoiler- Carbon Fiber Weave | C5: 7995 | D5: Not available at this time. | F5: spoilers, carbon_fiber | G5: Spoilers | H5: Wheel Accessories
A6: 5V7 | B6: Black Ground Effects | C6: 625 | D6: Includes STI and Front splitter. | E6: Requires 5V5, 5ZU, 5ZZ | F6: lpo | G6: Exterior Accessories | H6: Engine Appearance
A7: 5ZC | B7: Jake Logo wheel center caps | C7: 250 | F7: lpo, wheels | G7: Wheel Accessories | H7: Custom Delivery
A8: 5ZD | B8: Carbon Flash Center Caps w/ Crossed Flags logo | C8: 250 | F8: lpo, wheels | G8: Wheel Accessories | H8: Coupe Roof Panel
A9: 5ZU | B9: High Wing Spoiler- Body color | C9: 1350 | D9: Deletes T0A Z51 rear spoiler when ordered with Z51 Performance Package. | E9: Requires exterior color G8G Arctic White, GBA Black or GKZ Torch Red, Not available with 5V5, 5ZW, 5ZZ, TVS, | F9: spoilers, lpo | G9: Spoilers | H9: Interior Accessories
A10: 5ZW | B10: Visible carbon fiber two-stanchion spoiler, LPO | C10: 6225 | D10: Deletes T0A Z51 rear spoiler when ordered with Z51 Performance Package | E10: Not available with 5V5, 5ZU, 5ZZ, TVS | F10: spoilers, carbon_fiber | G10: Carbon Fiber | H10: Convertible Roof Panel
A11: 5ZZ | B11: High Wing Spoiler- Carbon Flash Painted | C11: 1395 | D11: Dealer Installed. Deletes T0A Z51 rear spoiler when ordered with Z51 Performance Package. | E11: Not available with 5V5, 5ZW, 5ZZ, TVS, | F11: spoilers, lpo | G11: Spoilers | H11: Stripes
A12: B6P | B12: Coupe Engine Appearance Package | C12: 1695 | D12: Includes Carbon Fiber Trim, D3V Engine Bay Lights, and SL9 Engine Specification Plaque | F12: engine_bay, carbon_fiber | G12: Engine Appearance | H12: Mechanical
A13: BC7 | B13: LT2 Engine Cover, Black | C13: 0 | D13: Standard on Coupe. Includes metal Corvette nameplate | E13: Requires ZZ3 Engine appearance package on Convertible. | F13: engine_bay | G13: Engine Appearance | H13: Accents
A14: BCP | B14: LPO, Engine Cover in Edge Red | C14: 495 | D14: Includes D3V Engine Bay Lights on Coupe. | E14: When equipped with B6P on Coupe. Requires ZZ3 Engine appearance package on Convertible. | F14: engine_bay, lpo | G14: Engine Appearance | H14: Badges
A15: BCP-s | B15: LPO, Engine Cover in Edge Red | C15: 595 | D15: Includes D3V Engine Bay Lights on Coupe. | E15: Not Equipped with B6P. Requires ZZ3 Engine appearance package on Convertible. | F15: engine_bay, lpo | G15: Engine Appearance | H15: Paint Color
A16: BCS | B16: LPO, Engine Cover in Sterling Silver | C16: 495 | D16: Silver with metal Corvette nameplate. | E16: When equipped with B6P on Coupe. Requires ZZ3 Engine appearance package on Convertible. | F16: engine_bay, lpo | G16: Engine Appearance | H16: Brake Calipers
A17: BCS-s | B17: LPO, Engine Cover in Sterling Silver | C17: 595 | D17: Includes D3V Engine Bay Lights on Coupe. | E17: Not Equipped with B6P. Requires ZZ3 Engine appearance package on Convertible. | F17: engine_bay, lpo | G17: Engine Appearance | H17: LPO Packages
A18: BV4 | B18: Plaque, personalized, custom-made with your name and VIN | C18: 295 | D18: Personalized plaque is included in museum delivery R8C, Plaque is located between the seats on the speaker grille. | F18: customdelivery | G18: Custom Delivery | H18: Wheels
A19: C2Z | B19: Visible Carbon Fiber weave w/body color border roof panel | C19: 2495 | F19: roof, carbon_fiber | G19: Coupe Roof Panel | H19: Car Covers
A20: CAV | B20: Contoured Cargo Area Liners w/ Jake logo | C20: 195 | D20: Included w/PEF. Stingray and Z06 include both cargo areas. E-Ray and ZR1 rear trunk only | F20: lpo | G20: Interior Accessories
A21: CC3 | B21: Transparent Glass roof panel | C21: 995 | F21: roof | G21: Coupe Roof Panel
A22: CF7 | B22: Body-Color Carbon Roof panel | C22: 0 | D22: Standard | F22: roof | G22: Coupe Roof Panel
A23: CF8 | B23: Electrochromic Dimming Roof Panel | C23: 3000 | D23: Electrochromic dimming, removable. | E23: Not available on 1LT, 1LZ. Not available with any Full Length Dual Racing Stripes (DPB, DPC, DPG, DPL, DPT, DSY, DSZ, DT0, DTB, DTH, DUB, DUK, DUW). | F23: roof | G23: Coupe Roof Panel
A24: CM9 | B24: Body-Color roof and nacelles | C24: 0 | D24: Standard | F24: roof | G24: Convertible Roof Panel
A25: D3V | B25: Engine Bay, Lights only | C25: 100 | D25: Coupe Only. Included with BCP, BCS, B6P, BCW. | F25: engine_bay | G25: Engine Appearance
A26: D84 | B26: Carbon Flash painted nacelles and roof | C26: 1295 | D26: Not available w/ GBA Black | E26: Not available w/ GBA Black | F26: roof | G26: Convertible Roof Panel
A27: D86 | B27: Carbon Flash painted nacelles and body color roof | C27: 1295 | D27: Not available w/ GBA Black | E27: Not available w/ GBA Black | F27: roof | G27: Convertible Roof Panel
A28: DPB | B28: Carbon Flash with Blue accent Full Length Dual Racing Stripes | C28: 1195 | D28: Not available with exterior color GJV Riptide Blue Metallic, GMO Rapid Blue, or GXL Hysteria Purple. | E28: Not available with exterior color GJV Riptide Blue Metallic, GMO Rapid Blue, or GXL Hysteria Purple. | F28: stripes | G28: Stripes
A29: DPC | B29: Carbon Flash with Yellow accent Full Length Dual Racing Stripes | C29: 1195 | D29: Not available with exterior color GBK Competition Yellow Tintcoat Metallic. | E29: Not available with exterior color GBK Competition Yellow Tintcoat Metallic. | F29: stripes | G29: Stripes
A30: DPG | B30: Carbon Flash with Orange accent Full Length Dual Racing Stripes | C30: 1195 | D30: Not available with exterior color G26 Sebring Orange Tintcoat. | E30: Not available with exterior color G26 Sebring Orange Tintcoat. | F30: stripes | G30: Stripes
A31: DPL | B31: Carbon Flash with Red accent Full Length Dual Racing Stripes | C31: 1195 | D31: Not available with exterior color GKZ Torch Red or GPH Red Mist Metallic Tintcoat. | E31: Not available with exterior color GKZ Torch Red or GPH Red Mist Metallic Tintcoat. | F31: stripes | G31: Stripes
A32: DPT | B32: Carbon Flash with Silver accent Full Length Dual Racing Stripes | C32: 1195 | F32: stripes | G32: Stripes
A33: DSY | B33: Edge Orange Full Length Dual Racing Stripe | C33: 1195 | D33: Not available with exterior color G26 Sebring Orange Tintcoat. | E33: Not available with exterior color G26 Sebring Orange Tintcoat. | F33: stripes | G33: Stripes
A34: DSZ | B34: Edge Red Full Length Dual Racing Stripe | C34: 1195 | D34: Not available with exterior color GKZ Torch Red or GPH Red Mist Metallic Tintcoat. | E34: Not available with exterior color GKZ Torch Red or GPH Red Mist Metallic Tintcoat. | F34: stripes | G34: Stripes
A35: DT0 | B35: Competition Yellow Full Length Dual Racing Stripe | C35: 1195 | D35: Not available with exterior color GBK Competition Yellow Tintcoat Metallic. | E35: Not available with exterior color GBK Competition Yellow Tintcoat Metallic. | F35: stripes | G35: Stripes
A36: DTH | B36: Carbon Flash Full Length Dual Racing Stripe | C36: 1195 | F36: stripes | G36: Stripes
A37: DUB | B37: Sterling Silver Full Length Dual Racing Stripe | C37: 1195 | F37: stripes | G37: Stripes
A38: DUK | B38: Asymmetrical Adrenaline Red/Carbon Flash Full Length Dual Racing Stripes | C38: 1195 | D38: Not available with exterior color (GKZ) Torch Red or (GPH) Red Mist Metallic Tintcoat. | E38: Not available with exterior color (GKZ) Torch Red or (GPH) Red Mist Metallic Tintcoat. | F38: stripes | G38: Stripes
A39: DUW | B39: Edge Blue Full Length Dual Racing Stripe | C39: 1195 | D39: Not available with exterior color GJV Riptide Blue Metallic, GMO Rapid Blue, or GXL Hysteria Purple. | E39: Not available with exterior color GJV Riptide Blue Metallic, GMO Rapid Blue, or GXL Hysteria Purple. | F39: stripes | G39: Stripes
A40: DZU | B40: Stinger Stripe, Carbon Flash/ Competition Yellow | C40: 500 | D40: Not available with exterior color GBK Competition Yellow Tintcoat Metallic. | E40: Not available with exterior color GBK Competition Yellow Tintcoat Metallic. | F40: stripes | G40: Stripes
...

Sheet Sheet5
A1: Body Style | B1: 6157] | C1: 6157] | D1: 6157] | E1: [if | F1: [ | G1: [/if | H1: =textjoin("",true,E1,B1,F1,C1,G1,D1) -> [if 6157][6157][/if 6157]
A2: Trim Level | B2: 6158] | C2: 6158] | D2: 6158] | E2: [if | F2: [ | G2: [/if | H2: =textjoin("",true,E2,B2,F2,C2,G2,D2) -> [if 6158][6158][/if 6158]
A3: Config Total | B3: 6164] | C3: 6164] | D3: 6164] | E3: [if | F3: [ | G3: [/if | H3: =textjoin("",true,E3,B3,F3,C3,G3,D3) -> [if 6164][6164][/if 6164]
A4: Config Total1 | B4: 6165] | C4: 6165] | D4: 6165] | E4: [if | F4: [ | G4: [/if | H4: =textjoin("",true,E4,B4,F4,C4,G4,D4) -> [if 6165][6165][/if 6165]
A5: Color | B5: 6168] | C5: 6168] | D5: 6168] | E5: [if | F5: [ | G5: [/if | H5: =textjoin("",true,E5,B5,F5,C5,G5,D5) -> [if 6168][6168][/if 6168]
A6: Wheels | B6: 6169] | C6: 6169] | D6: 6169] | E6: [if | F6: [ | G6: [/if | H6: =textjoin("",true,E6,B6,F6,C6,G6,D6) -> [if 6169][6169][/if 6169]
A7: Backup Wheels | B7: 6172] | C7: 6172] | D7: 6172] | E7: [if | F7: [ | G7: [/if | H7: =textjoin("",true,E7,B7,F7,C7,G7,D7) -> [if 6172][6172][/if 6172]
A8: Brake Calipers | B8: 6174] | C8: 6174] | D8: 6174] | E8: [if | F8: [ | G8: [/if | H8: =textjoin("",true,E8,B8,F8,C8,G8,D8) -> [if 6174][6174][/if 6174]
A9: Coupe Roof Panel | B9: 6175] | C9: 6175] | D9: 6175] | E9: [if | F9: [ | G9: [/if | H9: =textjoin("",true,E9,B9,F9,C9,G9,D9) -> [if 6175][6175][/if 6175]
A10: Convertible Roof and Nacelles | B10: 6176] | C10: 6176] | D10: 6176] | E10: [if | F10: [ | G10: [/if | H10: =textjoin("",true,E10,B10,F10,C10,G10,D10) -> [if 6176][6176][/if 6176]
A11: GBA Roof Panel | B11: 6177] | C11: 6177] | D11: 6177] | E11: [if | F11: [ | G11: [/if | H11: =textjoin("",true,E11,B11,F11,C11,G11,D11) -> [if 6177][6177][/if 6177]
A12: Badges | B12: 6178] | C12: 6178] | D12: 6178] | E12: [if | F12: [ | G12: [/if | H12: =textjoin("",true,E12,B12,F12,C12,G12,D12) -> [if 6178][6178][/if 6178]
... A131: User ID | B131: 6375] | C131: 6375] | D131: 6375] | E131: [if | F131: [ | G131: [/if | H131: =textjoin("",true,E131,B131,F131,C131,G131,D131) -> [if 6375][6375][/if 6375]

Sheet Pivot Table 2

Sheet STINGRAY_INT
A1: Section | B1: Trim | C1: Seat | D1: RPO | E1: Suede | F1: Stitching | G1: Two Tone | H1: Name | I1: Detail | J1: Price | K1: Category | L1: Codes
A2: 1LT Colors | B2: 1LT | C2: AQ9 | D2: HTA | H2: Jet Black Mulan | I2: AQ9 GT1 Seats . Interior color on seats only. Stitching will match int color. Jet Black has silver stitching. | J2: =SUM( SUMIFS( PriceRef!$D$2:$D154, PriceRef!$A$2:$A154, "Seat", PriceRef!$B$2:$B154, $B2, PriceRef!$C$2:$C154, $C2 ), SUMIFS( PriceRef!$D$2:$D154, PriceRef!$A$2:$A154, "Stitching", PriceRef!$C$2:$C154, $F2 ), SUMIFS( PriceRef!$D$2:$D154, PriceRef!$A$2:$A154, "Suede", PriceRef!$C$2:$C154, $E2 ), SUMIFS( PriceRef!$D$2:$D154, PriceRef!$A$2:$A154, "TwoTone", PriceRef!$C$2:$C154, $G2 ) ) -> 0 | K2: interior.1 | L2: =textjoin(" ",true,B2,C2,D2,F2,E2,G2) -> 1LT AQ9 HTA
A3: 1LT Colors | B3: 1LT | C3: AE4 | D3: HTJ | E3: N26 | H3: Jet Black Performance Textile | I3: AE4 Comp Seats. Adds N26 suede steering wheel. Seat back and bottom are all performance textile. Interior color on seats only. Jet Black has silver stitching. | J3: =SUM( SUMIFS( PriceRef!$D$2:$D154, PriceRef!$A$2:$A154, "Seat", PriceRef!$B$2:$B154, $B3, PriceRef!$C$2:$C154, $C3 ), SUMIFS( PriceRef!$D$2:$D154, PriceRef!$A$2:$A154, "Stitching", PriceRef!$C$2:$C154, $F3 ), SUMIFS( PriceRef!$D$2:$D154, PriceRef!$A$2:$A154, "Suede", PriceRef!$C$2:$C154, $E3 ), SUMIFS( PriceRef!$D$2:$D154, PriceRef!$A$2:$A154, "TwoTone", PriceRef!$C$2:$C154, $G3 ) ) -> 695 | K3: interior.1 | L3: =textjoin(" ",true,B3,C3,D3,F3,E3,G3) -> 1LT AE4 HTJ N26
A4: 1LT Colors | B4: 1LT | C4: AQ9 | D4: HUP | H4: Sky Cool Gray Mulan | I4: AQ9 GT1 Seats. Interior color on seats only. Stitching will match int color. | J4: =SUM( SUMIFS( PriceRef!$D$2:$D154, PriceRef!$A$2:$A154, "Seat", PriceRef!$B$2:$B154, $B4, PriceRef!$C$2:$C154, $C4 ), SUMIFS( PriceRef!$D$2:$D154, PriceRef!$A$2:$A154, "Stitching", PriceRef!$C$2:$C154, $F4 ), SUMIFS( PriceRef!$D$2:$D154, PriceRef!$A$2:$A154, "Suede", PriceRef!$C$2:$C154, $E4 ), SUMIFS( PriceRef!$D$2:$D154, PriceRef!$A$2:$A154, "TwoTone", PriceRef!$C$2:$C154, $G4 ) ) -> 0 | K4: interior.1 | L4: =textjoin(" ",true,B4,C4,D4,F4,E4,G4) -> 1LT AQ9 HUP
A5: 1LT Colors | B5: 1LT | C5: AQ9 | D5: HUQ | H5: Adrenaline Red Mulan | I5: AQ9 GT1 Seats. Interior color on seats only. Stitching will match int color. | J5: =SUM( SUMIFS( PriceRef!$D$2:$D154, PriceRef!$A$2:$A154, "Seat", PriceRef!$B$2:$B154, $B5, PriceRef!$C$2:$C154, $C5 ), SUMIFS( PriceRef!$D$2:$D154, PriceRef!$A$2:$A154, "Stitching", PriceRef!$C$2:$C154, $F5 ), SUMIFS( PriceRef!$D$2:$D154, PriceRef!$A$2:$A154, "Suede", PriceRef!$C$2:$C154, $E5 ), SUMIFS( PriceRef!$D$2:$D154, PriceRef!$A$2:$A154, "TwoTone", PriceRef!$C$2:$C154, $G5 ) ) -> 0 | K5: interior.1 | L5: =textjoin(" ",true,B5,C5,D5,F5,E5,G5) -> 1LT AQ9 HUQ
A6: 1LT Seats | B6: 1LT | C6: AE4 | D6: AE4 | H6: Competition Sport Bucket seats | I6: Performance textile seating surface. Requires N26 Suede wrapped steering wheel $695 | J6: =SUM( SUMIFS( PriceRef!$D$2:$D154, PriceRef!$A$2:$A154, "Seat", PriceRef!$B$2:$B154, $B6, PriceRef!$C$2:$C154, $C6 ), SUMIFS( PriceRef!$D$2:$D154, PriceRef!$A$2:$A154, "Stitching", PriceRef!$C$2:$C154, $F6 ), SUMIFS( PriceRef!$D$2:$D154, PriceRef!$A$2:$A154, "Suede", PriceRef!$C$2:$C154, $E6 ), SUMIFS( PriceRef!$D$2:$D154, PriceRef!$A$2:$A154, "TwoTone", PriceRef!$C$2:$C154, $G6 ) ) -> 0 | K6: interior.1s | L6: =textjoin(" ",true,B6,C6,D6,F6,E6,G6) -> 1LT AE4 AE4
A7: 1LT Seats | B7: 1LT | C7: AQ9 | D7: AQ9 | H7: GT1 Bucket seats | I7: Mulan Leather | J7: =SUM( SUMIFS( PriceRef!$D$2:$D154, PriceRef!$A$2:$A154, "Seat", PriceRef!$B$2:$B154, $B7, PriceRef!$C$2:$C154, $C7 ), SUMIFS( PriceRef!$D$2:$D154, PriceRef!$A$2:$A154, "Stitching", PriceRef!$C$2:$C154, $F7 ), SUMIFS( PriceRef!$D$2:$D154, PriceRef!$A$2:$A154, "Suede", PriceRef!$C$2:$C154, $E7 ), SUMIFS( PriceRef!$D$2:$D154, PriceRef!$A$2:$A154, "TwoTone", PriceRef!$C$2:$C154, $G7 ) ) -> 0 | K7: interior.1s | L7: =textjoin(" ",true,B7,C7,D7,F7,E7,G7) -> 1LT AQ9 AQ9
A8: 2LT Colors | B8: 2LT | C8: AQ9 | D8: H1Y | H8: Jet Black Mulan | I8: AQ9 GT1 Seats. Interior color is on seats, doors, and console trim. Jet Black has silver stitching. | J8: =SUM( SUMIFS( PriceRef!$D$2:$D154, PriceRef!$A$2:$A154, "Seat", PriceRef!$B$2:$B154, $B8, PriceRef!$C$2:$C154, $C8 ), SUMIFS( PriceRef!$D$2:$D154, PriceRef!$A$2:$A154, "Stitching", PriceRef!$C$2:$C154, $F8 ), SUMIFS( PriceRef!$D$2:$D154, PriceRef!$A$2:$A154, "Suede", PriceRef!$C$2:$C154, $E8 ), SUMIFS( PriceRef!$D$2:$D154, PriceRef!$A$2:$A154, "TwoTone", PriceRef!$C$2:$C154, $G8 ) ) -> 0 | K8: interior.2 | L8: =textjoin(" ",true,B8,C8,D8,F8,E8,G8) -> 2LT AQ9 H1Y
A9: 2LT Colors | B9: 2LT | C9: AQ9 | D9: H1Y | F9: 38S | H9: Jet Black Mulan with Red Stitching | I9: AQ9 GT1 Seats. Interior color is on seats, doors, and console trim. | J9: =SUM( SUMIFS( PriceRef!$D$2:$D154, PriceRef!$A$2:$A154, "Seat", PriceRef!$B$2:$B154, $B9, PriceRef!$C$2:$C154, $C9 ), SUMIFS( PriceRef!$D$2:$D154, PriceRef!$A$2:$A154, "Stitching", PriceRef!$C$2:$C154, $F9 ), SUMIFS( PriceRef!$D$2:$D154, PriceRef!$A$2:$A154, "Suede", PriceRef!$C$2:$C154, $E9 ), SUMIFS( PriceRef!$D$2:$D154, PriceRef!$A$2:$A154, "TwoTone", PriceRef!$C$2:$C154, $G9 ) ) -> 495 | K9: interior.2 | L9: =textjoin(" ",true,B9,C9,D9,F9,E9,G9) -> 2LT AQ9 H1Y 38S
A10: 2LT Colors | B10: 2LT | C10: AQ9 | D10: H1Y | F10: 36S | H10: Jet Black Mulan with Yellow Stitching | I10: AQ9 GT1 Seats. Interior color is on seats, doors, and console trim. | J10: =SUM( SUMIFS( PriceRef!$D$2:$D154, PriceRef!$A$2:$A154, "Seat", PriceRef!$B$2:$B154, $B10, PriceRef!$C$2:$C154, $C10 ), SUMIFS( PriceRef!$D$2:$D154, PriceRef!$A$2:$A154, "Stitching", PriceRef!$C$2:$C154, $F10 ), SUMIFS( PriceRef!$D$2:$D154, PriceRef!$A$2:$A154, "Suede", PriceRef!$C$2:$C154, $E10 ), SUMIFS( PriceRef!$D$2:$D154, PriceRef!$A$2:$A154, "TwoTone", PriceRef!$C$2:$C154, $G10 ) ) -> 495 | K10: interior.2 | L10: =textjoin(" ",true,B10,C10,D10,F10,E10,G10) -> 2LT AQ9 H1Y 36S
A11: 2LT Colors | B11: 2LT | C11: AQ9 | D11: H1Y | F11: 37S | H11: Jet Black Mulan with Blue Stitching | I11: AQ9 GT1 Seats. Interior color is on seats, doors, and console trim. | J11: =SUM( SUMIFS( PriceRef!$D$2:$D154, PriceRef!$A$2:$A154, "Seat", PriceRef!$B$2:$B154, $B11, PriceRef!$C$2:$C154, $C11 ), SUMIFS( PriceRef!$D$2:$D154, PriceRef!$A$2:$A154, "Stitching", PriceRef!$C$2:$C154, $F11 ), SUMIFS( PriceRef!$D$2:$D154, PriceRef!$A$2:$A154, "Suede", PriceRef!$C$2:$C154, $E11 ), SUMIFS( PriceRef!$D$2:$D154, PriceRef!$A$2:$A154, "TwoTone", PriceRef!$C$2:$C154, $G11 ) ) -> 495 | K11: interior.2 | L11: =textjoin(" ",true,B11,C11,D11,F11,E11,G11) -> 2LT AQ9 H1Y 37S
A12: 2LT Colors | B12: 2LT | C12: AH2 | D12: HTM | H12: Jet Black Napa | I12: AH2 GT2 seats. Interior color is on seats, doors, and console trim. Jet Black has silver stitching. | J12: =SUM( SUMIFS( PriceRef!$D$2:$D154, PriceRef!$A$2:$A154, "Seat", PriceRef!$B$2:$B154, $B12, PriceRef!$C$2:$C154, $C12 ), SUMIFS( PriceRef!$D$2:$D154, PriceRef!$A$2:$A154, "Stitching", PriceRef!$C$2:$C154, $F12 ), SUMIFS( PriceRef!$D$2:$D154, PriceRef!$A$2:$A154, "Suede", PriceRef!$C$2:$C154, $E12 ), SUMIFS( PriceRef!$D$2:$D154, PriceRef!$A$2:$A154, "TwoTone", PriceRef!$C$2:$C154, $G12 ) ) -> 1695 | K12: interior.2 | L12: =textjoin(" ",true,B12,C12,D12,F12,E12,G12) -> 2LT AH2 HTM
A13: 2LT Colors | B13: 2LT | C13: AH2 | D13: HTM | F13: 38S | H13: Jet Black Napa with Red Stitching | I13: AH2 GT2 seats. Interior color is on seats, doors, and console trim. | J13: =SUM( SUMIFS( PriceRef!$D$2:$D154, PriceRef!$A$2:$A154, "Seat", PriceRef!$B$2:$B154, $B13, PriceRef!$C$2:$C154, $C13 ), SUMIFS( PriceRef!$D$2:$D154, PriceRef!$A$2:$A154, "Stitching", PriceRef!$C$2:$C154, $F13 ), SUMIFS( PriceRef!$D$2:$D154, PriceRef!$A$2:$A154, "Suede", PriceRef!$C$2:$C154, $E13 ), SUMIFS( PriceRef!$D$2:$D154, PriceRef!$A$2:$A154, "TwoTone", PriceRef!$C$2:$C154, $G13 ) ) -> 2190 | K13: interior.2 | L13: =textjoin(" ",true,B13,C13,D13,F13,E13,G13) -> 2LT AH2 HTM 38S
A14: 2LT Colors | B14: 2LT | C14: AH2 | D14: HTM | F14: 36S | H14: Jet Black Napa with Yellow Stitching | I14: AH2 GT2 seats. Interior color is on seats, doors, and console trim. | J14: =SUM( SUMIFS( PriceRef!$D$2:$D154, PriceRef!$A$2:$A154, "Seat", PriceRef!$B$2:$B154, $B14, PriceRef!$C$2:$C154, $C14 ), SUMIFS( PriceRef!$D$2:$D154, PriceRef!$A$2:$A154, "Stitching", PriceRef!$C$2:$C154, $F14 ), SUMIFS( PriceRef!$D$2:$D154, PriceRef!$A$2:$A154, "Suede", PriceRef!$C$2:$C154, $E14 ), SUMIFS( PriceRef!$D$2:$D154, PriceRef!$A$2:$A154, "TwoTone", PriceRef!$C$2:$C154, $G14 ) ) -> 2190 | K14: interior.2 | L14: =textjoin(" ",true,B14,C14,D14,F14,E14,G14) -> 2LT AH2 HTM 36S
A15: 2LT Colors | B15: 2LT | C15: AH2 | D15: HTM | F15: 37S | H15: Jet Black Napa with Blue Stitching | I15: AH2 GT2 seats. Interior color is on seats, doors, and console trim. | J15: =SUM( SUMIFS( PriceRef!$D$2:$D154, PriceRef!$A$2:$A154, "Seat", PriceRef!$B$2:$B154, $B15, PriceRef!$C$2:$C154, $C15 ), SUMIFS( PriceRef!$D$2:$D154, PriceRef!$A$2:$A154, "Stitching", PriceRef!$C$2:$C154, $F15 ), SUMIFS( PriceRef!$D$2:$D154, PriceRef!$A$2:$A154, "Suede", PriceRef!$C$2:$C154, $E15 ), SUMIFS( PriceRef!$D$2:$D154, PriceRef!$A$2:$A154, "TwoTone", PriceRef!$C$2:$C154, $G15 ) ) -> 2190 | K15: interior.2 | L15: =textjoin(" ",true,B15,C15,D15,F15,E15,G15) -> 2LT AH2 HTM 37S
A16: 2LT Colors | B16: 2LT | C16: AE4 | D16: HTM | H16: Jet Black Napa | I16: AE4 Comp Seats. Interior color is on seats, doors, and console trim. Jet Black has silver stitching. | J16: =SUM( SUMIFS( PriceRef!$D$2:$D154, PriceRef!$A$2:$A154, "Seat", PriceRef!$B$2:$B154, $B16, PriceRef!$C$2:$C154, $C16 ), SUMIFS( PriceRef!$D$2:$D154, PriceRef!$A$2:$A154, "Stitching", PriceRef!$C$2:$C154, $F16 ), SUMIFS( PriceRef!$D$2:$D154, PriceRef!$A$2:$A154, "Suede", PriceRef!$C$2:$C154, $E16 ), SUMIFS( PriceRef!$D$2:$D154, PriceRef!$A$2:$A154, "TwoTone", PriceRef!$C$2:$C154, $G16 ) ) -> 1995 | K16: interior.2 | L16: =textjoin(" ",true,B16,C16,D16,F16,E16,G16) -> 2LT AE4 HTM
A17: 2LT Colors | B17: 2LT | C17: AE4 | D17: HTM | F17: 38S | H17: Jet Black Napa with Red Stitching | I17: AE4 Comp Seats. Interior color is on seats, doors, and console trim. | J17: =SUM( SUMIFS( PriceRef!$D$2:$D154, PriceRef!$A$2:$A154, "Seat", PriceRef!$B$2:$B154, $B17, PriceRef!$C$2:$C154, $C17 ), SUMIFS( PriceRef!$D$2:$D154, PriceRef!$A$2:$A154, "Stitching", PriceRef!$C$2:$C154, $F17 ), SUMIFS( PriceRef!$D$2:$D154, PriceRef!$A$2:$A154, "Suede", PriceRef!$C$2:$C154, $E17 ), SUMIFS( PriceRef!$D$2:$D154, PriceRef!$A$2:$A154, "TwoTone", PriceRef!$C$2:$C154, $G17 ) ) -> 2490 | K17: interior.2 | L17: =textjoin(" ",true,B17,C17,D17,F17,E17,G17) -> 2LT AE4 HTM 38S
A18: 2LT Colors | B18: 2LT | C18: AE4 | D18: HTM | F18: 36S | H18: Jet Black Napa with Yellow Stitching | I18: AE4 Comp Seats. Interior color is on seats, doors, and console trim. | J18: =SUM( SUMIFS( PriceRef!$D$2:$D154, PriceRef!$A$2:$A154, "Seat", PriceRef!$B$2:$B154, $B18, PriceRef!$C$2:$C154, $C18 ), SUMIFS( PriceRef!$D$2:$D154, PriceRef!$A$2:$A154, "Stitching", PriceRef!$C$2:$C154, $F18 ), SUMIFS( PriceRef!$D$2:$D154, PriceRef!$A$2:$A154, "Suede", PriceRef!$C$2:$C154, $E18 ), SUMIFS( PriceRef!$D$2:$D154, PriceRef!$A$2:$A154, "TwoTone", PriceRef!$C$2:$C154, $G18 ) ) -> 2490 | K18: interior.2 | L18: =textjoin(" ",true,B18,C18,D18,F18,E18,G18) -> 2LT AE4 HTM 36S
A19: 2LT Colors | B19: 2LT | C19: AE4 | D19: HTM | F19: 37S | H19: Jet Black Napa with Blue Stitching | I19: AE4 Comp Seats. Interior color is on seats, doors, and console trim. | J19: =SUM( SUMIFS( PriceRef!$D$2:$D154, PriceRef!$A$2:$A154, "Seat", PriceRef!$B$2:$B154, $B19, PriceRef!$C$2:$C154, $C19 ), SUMIFS( PriceRef!$D$2:$D154, PriceRef!$A$2:$A154, "Stitching", PriceRef!$C$2:$C154, $F19 ), SUMIFS( PriceRef!$D$2:$D154, PriceRef!$A$2:$A154, "Suede", PriceRef!$C$2:$C154, $E19 ), SUMIFS( PriceRef!$D$2:$D154, PriceRef!$A$2:$A154, "TwoTone", PriceRef!$C$2:$C154, $G19 ) ) -> 2490 | K19: interior.2 | L19: =textjoin(" ",true,B19,C19,D19,F19,E19,G19) -> 2LT AE4 HTM 37S
A20: 2LT Colors | B20: 2LT | C20: AH2 | D20: HTN | H20: Natural Napa | I20: AH2 GT2 Seats. Interior color is on seats, doors, and console trim. TU7 Two tone seats available with GT2 seats | J20: =SUM( SUMIFS( PriceRef!$D$2:$D154, PriceRef!$A$2:$A154, "Seat", PriceRef!$B$2:$B154, $B20, PriceRef!$C$2:$C154, $C20 ), SUMIFS( PriceRef!$D$2:$D154, PriceRef!$A$2:$A154, "Stitching", PriceRef!$C$2:$C154, $F20 ), SUMIFS( PriceRef!$D$2:$D154, PriceRef!$A$2:$A154, "Suede", PriceRef!$C$2:$C154, $E20 ), SUMIFS( PriceRef!$D$2:$D154, PriceRef!$A$2:$A154, "TwoTone", PriceRef!$C$2:$C154, $G20 ) ) -> 1695 | K20: interior.2 | L20: =textjoin(" ",true,B20,C20,D20,F20,E20,G20) -> 2LT AH2 HTN
A21: 2LT Colors | B21: 2LT | C21: AE4 | D21: HTN | H21: Natural Napa | I21: AE4 Comp Seats. Interior color is on seats, doors, and console trim. | J21: =SUM( SUMIFS( PriceRef!$D$2:$D154, PriceRef!$A$2:$A154, "Seat", PriceRef!$B$2:$B154, $B21, PriceRef!$C$2:$C154, $C21 ), SUMIFS( PriceRef!$D$2:$D154, PriceRef!$A$2:$A154, "Stitching", PriceRef!$C$2:$C154, $F21 ), SUMIFS( PriceRef!$D$2:$D154, PriceRef!$A$2:$A154, "Suede", PriceRef!$C$2:$C154, $E21 ), SUMIFS( PriceRef!$D$2:$D154, PriceRef!$A$2:$A154, "TwoTone", PriceRef!$C$2:$C154, $G21 ) ) -> 1995 | K21: interior.2 | L21: =textjoin(" ",true,B21,C21,D21,F21,E21,G21) -> 2LT AE4 HTN
A22: 2LT Colors | B22: 2LT | C22: AH2 | D22: HTN | G22: TU7 | H22: Natural Napa with two tone seats | I22: AH2 GT2 Seats. Interior color is on seats, doors, and console trim. TU7 Two tone adds black seat inserts and headrest. | J22: =SUM( SUMIFS( PriceRef!$D$2:$D154, PriceRef!$A$2:$A154, "Seat", PriceRef!$B$2:$B154, $B22, PriceRef!$C$2:$C154, $C22 ), SUMIFS( PriceRef!$D$2:$D154, PriceRef!$A$2:$A154, "Stitching", PriceRef!$C$2:$C154, $F22 ), SUMIFS( PriceRef!$D$2:$D154, PriceRef!$A$2:$A154, "Suede", PriceRef!$C$2:$C154, $E22 ), SUMIFS( PriceRef!$D$2:$D154, PriceRef!$A$2:$A154, "TwoTone", PriceRef!$C$2:$C154, $G22 ) ) -> 2290 | K22: interior.2 | L22: =textjoin(" ",true,B22,C22,D22,F22,E22,G22) -> 2LT AH2 HTN TU7
A23: 2LT Colors | B23: 2LT | C23: AH2 | D23: HTP | E23: N26 | H23: Jet Black Napa with sueded microfiber inserts | I23: AH2 GT2 Seats. Includes Suede Steering Wheel. Interior color is on seats, doors, and console trim. Jet Black has silver stitching. | J23: =SUM( SUMIFS( PriceRef!$D$2:$D154, PriceRef!$A$2:$A154, "Seat", PriceRef!$B$2:$B154, $B23, PriceRef!$C$2:$C154, $C23 ), SUMIFS( PriceRef!$D$2:$D154, PriceRef!$A$2:$A154, "Stitching", PriceRef!$C$2:$C154, $F23 ), SUMIFS( PriceRef!$D$2:$D154, PriceRef!$A$2:$A154, "Suede", PriceRef!$C$2:$C154, $E23 ), SUMIFS( PriceRef!$D$2:$D154, PriceRef!$A$2:$A154, "TwoTone", PriceRef!$C$2:$C154, $G23 ) ) -> 2390 | K23: interior.2 | L23: =textjoin(" ",true,B23,C23,D23,F23,E23,G23) -> 2LT AH2 HTP N26
A24: 2LT Colors | B24: 2LT | C24: AH2 | D24: HTP | E24: N26 | F24: 38S | H24: Jet Black Napa with sueded microfiber inserts and Red Stitching | I24: AH2 GT2 Seats. Includes Suede Steering Wheel. Interior color is on seats, doors, and console trim. Jet Black has silver stitching. | J24: =SUM( SUMIFS( PriceRef!$D$2:$D154, PriceRef!$A$2:$A154, "Seat", PriceRef!$B$2:$B154, $B24, PriceRef!$C$2:$C154, $C24 ), SUMIFS( PriceRef!$D$2:$D154, PriceRef!$A$2:$A154, "Stitching", PriceRef!$C$2:$C154, $F24 ), SUMIFS( PriceRef!$D$2:$D154, PriceRef!$A$2:$A154, "Suede", PriceRef!$C$2:$C154, $E24 ), SUMIFS( PriceRef!$D$2:$D154, PriceRef!$A$2:$A154, "TwoTone", PriceRef!$C$2:$C154, $G24 ) ) -> 2885 | K24: interior.2 | L24: =textjoin(" ",true,B24,C24,D24,F24,E24,G24) -> 2LT AH2 HTP 38S N26
A25: 2LT Colors | B25: 2LT | C25: AH2 | D25: HTP | E25: N26 | F25: 36S | H25: Jet Black Napa with sueded microfiber inserts and Yellow Stitching | I25: AH2 GT2 Seats. Includes Suede Steering Wheel. Interior color is on seats, doors, and console trim. Jet Black has silver stitching. | J25: =SUM( SUMIFS( PriceRef!$D$2:$D154, PriceRef!$A$2:$A154, "Seat", PriceRef!$B$2:$B154, $B25, PriceRef!$C$2:$C154, $C25 ), SUMIFS( PriceRef!$D$2:$D154, PriceRef!$A$2:$A154, "Stitching", PriceRef!$C$2:$C154, $F25 ), SUMIFS( PriceRef!$D$2:$D154, PriceRef!$A$2:$A154, "Suede", PriceRef!$C$2:$C154, $E25 ), SUMIFS( PriceRef!$D$2:$D154, PriceRef!$A$2:$A154, "TwoTone", PriceRef!$C$2:$C154, $G25 ) ) -> 2885 | K25: interior.2 | L25: =textjoin(" ",true,B25,C25,D25,F25,E25,G25) -> 2LT AH2 HTP 36S N26
A26: 2LT Colors | B26: 2LT | C26: AH2 | D26: HTP | E26: N26 | F26: 37S | H26: Jet Black Napa with sueded microfiber inserts and Blue Stitching | I26: AH2 GT2 Seats. Includes Suede Steering Wheel. Interior color is on seats, doors, and console trim. Jet Black has silver stitching. | J26: =SUM( SUMIFS( PriceRef!$D$2:$D154, PriceRef!$A$2:$A154, "Seat", PriceRef!$B$2:$B154, $B26, PriceRef!$C$2:$C154, $C26 ), SUMIFS( PriceRef!$D$2:$D154, PriceRef!$A$2:$A154, "Stitching", PriceRef!$C$2:$C154, $F26 ), SUMIFS( PriceRef!$D$2:$D154, PriceRef!$A$2:$A154, "Suede", PriceRef!$C$2:$C154, $E26 ), SUMIFS( PriceRef!$D$2:$D154, PriceRef!$A$2:$A154, "TwoTone", PriceRef!$C$2:$C154, $G26 ) ) -> 2885 | K26: interior.2 | L26: =textjoin(" ",true,B26,C26,D26,F26,E26,G26) -> 2LT AH2 HTP 37S N26
A27: 2LT Colors | B27: 2LT | C27: AE4 | D27: HTP | E27: N26 | H27: Jet Black Napa with sueded microfiber inserts | I27: AE4 Comp Seats. Includes Suede Steering Wheel. Interior color is on seats, doors, and console trim. Jet Black has silver stitching. | J27: =SUM( SUMIFS( PriceRef!$D$2:$D154, PriceRef!$A$2:$A154, "Seat", PriceRef!$B$2:$B154, $B27, PriceRef!$C$2:$C154, $C27 ), SUMIFS( PriceRef!$D$2:$D154, PriceRef!$A$2:$A154, "Stitching", PriceRef!$C$2:$C154, $F27 ), SUMIFS( PriceRef!$D$2:$D154, PriceRef!$A$2:$A154, "Suede", PriceRef!$C$2:$C154, $E27 ), SUMIFS( PriceRef!$D$2:$D154, PriceRef!$A$2:$A154, "TwoTone", PriceRef!$C$2:$C154, $G27 ) ) -> 2690 | K27: interior.2 | L27: =textjoin(" ",true,B27,C27,D27,F27,E27,G27) -> 2LT AE4 HTP N26
A28: 2LT Colors | B28: 2LT | C28: AE4 | D28: HTP | E28: N26 | F28: 38S | H28: Jet Black Napa with sueded microfiber inserts and Red Stitching | I28: AE4 Comp Seats. Includes Suede Steering Wheel. Interior color is on seats, doors, and console trim. Jet Black has silver stitching. | J28: =SUM( SUMIFS( PriceRef!$D$2:$D154, PriceRef!$A$2:$A154, "Seat", PriceRef!$B$2:$B154, $B28, PriceRef!$C$2:$C154, $C28 ), SUMIFS( PriceRef!$D$2:$D154, PriceRef!$A$2:$A154, "Stitching", PriceRef!$C$2:$C154, $F28 ), SUMIFS( PriceRef!$D$2:$D154, PriceRef!$A$2:$A154, "Suede", PriceRef!$C$2:$C154, $E28 ), SUMIFS( PriceRef!$D$2:$D154, PriceRef!$A$2:$A154, "TwoTone", PriceRef!$C$2:$C154, $G28 ) ) -> 3185 | K28: interior.2 | L28: =textjoin(" ",true,B28,C28,D28,F28,E28,G28) -> 2LT AE4 HTP 38S N26
A29: 2LT Colors | B29: 2LT | C29: AE4 | D29: HTP | E29: N26 | F29: 36S | H29: Jet Black Napa with sueded microfiber inserts and Yellow Stitching | I29: AE4 Comp Seats. Includes Suede Steering Wheel. Interior color is on seats, doors, and console trim. Jet Black has silver stitching. | J29: =SUM( SUMIFS( PriceRef!$D$2:$D154, PriceRef!$A$2:$A154, "Seat", PriceRef!$B$2:$B154, $B29, PriceRef!$C$2:$C154, $C29 ), SUMIFS( PriceRef!$D$2:$D154, PriceRef!$A$2:$A154, "Stitching", PriceRef!$C$2:$C154, $F29 ), SUMIFS( PriceRef!$D$2:$D154, PriceRef!$A$2:$A154, "Suede", PriceRef!$C$2:$C154, $E29 ), SUMIFS( PriceRef!$D$2:$D154, PriceRef!$A$2:$A154, "TwoTone", PriceRef!$C$2:$C154, $G29 ) ) -> 3185 | K29: interior.2 | L29: =textjoin(" ",true,B29,C29,D29,F29,E29,G29) -> 2LT AE4 HTP 36S N26
A30: 2LT Colors | B30: 2LT | C30: AE4 | D30: HTP | E30: N26 | F30: 37S | H30: Jet Black Napa with sueded microfiber inserts and Blue Stitching | I30: AE4 Comp Seats. Includes Suede Steering Wheel. Interior color is on seats, doors, and console trim. Jet Black has silver stitching. | J30: =SUM( SUMIFS( PriceRef!$D$2:$D154, PriceRef!$A$2:$A154, "Seat", PriceRef!$B$2:$B154, $B30, PriceRef!$C$2:$C154, $C30 ), SUMIFS( PriceRef!$D$2:$D154, PriceRef!$A$2:$A154, "Stitching", PriceRef!$C$2:$C154, $F30 ), SUMIFS( PriceRef!$D$2:$D154, PriceRef!$A$2:$A154, "Suede", PriceRef!$C$2:$C154, $E30 ), SUMIFS( PriceRef!$D$2:$D154, PriceRef!$A$2:$A154, "TwoTone", PriceRef!$C$2:$C154, $G30 ) ) -> 3185 | K30: interior.2 | L30: =textjoin(" ",true,B30,C30,D30,F30,E30,G30) -> 2LT AE4 HTP 37S N26
A31: 2LT Colors | B31: 2LT | C31: AH2 | D31: HTQ | E31: N26 | H31: Natural Napa with sueded microfiber inserts | I31: AH2 GT2 seats. Includes Suede Steering Wheel. Interior color is on seats, doors, and console trim. TU7 Two tone seats available with GT2 seats | J31: =SUM( SUMIFS( PriceRef!$D$2:$D154, PriceRef!$A$2:$A154, "Seat", PriceRef!$B$2:$B154, $B31, PriceRef!$C$2:$C154, $C31 ), SUMIFS( PriceRef!$D$2:$D154, PriceRef!$A$2:$A154, "Stitching", PriceRef!$C$2:$C154, $F31 ), SUMIFS( PriceRef!$D$2:$D154, PriceRef!$A$2:$A154, "Suede", PriceRef!$C$2:$C154, $E31 ), SUMIFS( PriceRef!$D$2:$D154, PriceRef!$A$2:$A154, "TwoTone", PriceRef!$C$2:$C154, $G31 ) ) -> 2390 | K31: interior.2 | L31: =textjoin(" ",true,B31,C31,D31,F31,E31,G31) -> 2LT AH2 HTQ N26
A32: 2LT Colors | B32: 2LT | C32: AE4 | D32: HTQ | E32: N26 | H32: Natural Napa with sueded microfiber inserts | I32: AE4 Comp Seats only. Includes Suede Steering Wheel. Interior color is on seats, doors, and console trim. | J32: =SUM( SUMIFS( PriceRef!$D$2:$D154, PriceRef!$A$2:$A154, "Seat", PriceRef!$B$2:$B154, $B32, PriceRef!$C$2:$C154, $C32 ), SUMIFS( PriceRef!$D$2:$D154, PriceRef!$A$2:$A154, "Stitching", PriceRef!$C$2:$C154, $F32 ), SUMIFS( PriceRef!$D$2:$D154, PriceRef!$A$2:$A154, "Suede", PriceRef!$C$2:$C154, $E32 ), SUMIFS( PriceRef!$D$2:$D154, PriceRef!$A$2:$A154, "TwoTone", PriceRef!$C$2:$C154, $G32 ) ) -> 2690 | K32: interior.2 | L32: =textjoin(" ",true,B32,C32,D32,F32,E32,G32) -> 2LT AE4 HTQ N26
A33: 2LT Colors | B33: 2LT | C33: AH2 | D33: HTQ | E33: N26 | G33: TU7 | H33: Natural Napa with sueded microfiber inserts and two tone seats | I33: AH2 GT2 seats. Includes Suede Steering Wheel. Interior color is on seats, doors, and console trim. TU7 Two tone adds black seat inserts and headrest. | J33: =SUM( SUMIFS( PriceRef!$D$2:$D154, PriceRef!$A$2:$A154, "Seat", PriceRef!$B$2:$B154, $B33, PriceRef!$C$2:$C154, $C33 ), SUMIFS( PriceRef!$D$2:$D154, PriceRef!$A$2:$A154, "Stitching", PriceRef!$C$2:$C154, $F33 ), SUMIFS( PriceRef!$D$2:$D154, PriceRef!$A$2:$A154, "Suede", PriceRef!$C$2:$C154, $E33 ), SUMIFS( PriceRef!$D$2:$D154, PriceRef!$A$2:$A154, "TwoTone", PriceRef!$C$2:$C154, $G33 ) ) -> 2985 | K33: interior.2 | L33: =textjoin(" ",true,B33,C33,D33,F33,E33,G33) -> 2LT AH2 HTQ N26 TU7
A34: 2LT Colors | B34: 2LT | C34: AH2 | D34: HU6 | E34: N26 | H34: Sky Cool Gray Napa with sueded microfiber inserts | I34: AH2 GT2 Seats. Includes Suede Steering Wheel. Interior color is on seats, doors, and console trim. TU7 Two tone seats available with GT2 seats | J34: =SUM( SUMIFS( PriceRef!$D$2:$D154, PriceRef!$A$2:$A154, "Seat", PriceRef!$B$2:$B154, $B34, PriceRef!$C$2:$C154, $C34 ), SUMIFS( PriceRef!$D$2:$D154, PriceRef!$A$2:$A154, "Stitching", PriceRef!$C$2:$C154, $F34 ), SUMIFS( PriceRef!$D$2:$D154, PriceRef!$A$2:$A154, "Suede", PriceRef!$C$2:$C154, $E34 ), SUMIFS( PriceRef!$D$2:$D154, PriceRef!$A$2:$A154, "TwoTone", PriceRef!$C$2:$C154, $G34 ) ) -> 2390 | K34: interior.2 | L34: =textjoin(" ",true,B34,C34,D34,F34,E34,G34) -> 2LT AH2 HU6 N26
A35: 2LT Colors | B35: 2LT | C35: AE4 | D35: HU6 | E35: N26 | H35: Sky Cool Gray Napa with sueded microfiber inserts | I35: AE4 Comp Seats are black. Includes Suede Steering Wheel. Interior color is on seats, doors, and console trim. | J35: =SUM( SUMIFS( PriceRef!$D$2:$D154, PriceRef!$A$2:$A154, "Seat", PriceRef!$B$2:$B154, $B35, PriceRef!$C$2:$C154, $C35 ), SUMIFS( PriceRef!$D$2:$D154, PriceRef!$A$2:$A154, "Stitching", PriceRef!$C$2:$C154, $F35 ), SUMIFS( PriceRef!$D$2:$D154, PriceRef!$A$2:$A154, "Suede", PriceRef!$C$2:$C154, $E35 ), SUMIFS( PriceRef!$D$2:$D154, PriceRef!$A$2:$A154, "TwoTone", PriceRef!$C$2:$C154, $G35 ) ) -> 2690 | K35: interior.2 | L35: =textjoin(" ",true,B35,C35,D35,F35,E35,G35) -> 2LT AE4 HU6 N26
A36: 2LT Colors | B36: 2LT | C36: AH2 | D36: HU6 | E36: N26 | G36: TU7 | H36: Sky Cool Gray Napa with sueded microfiber inserts and two tone seats | I36: AH2 GT2 Seats. Includes Suede Steering Wheel. Interior color is on seats, doors, and console trim. TU7 Two tone adds black seat inserts and headrest. | J36: =SUM( SUMIFS( PriceRef!$D$2:$D154, PriceRef!$A$2:$A154, "Seat", PriceRef!$B$2:$B154, $B36, PriceRef!$C$2:$C154, $C36 ), SUMIFS( PriceRef!$D$2:$D154, PriceRef!$A$2:$A154, "Stitching", PriceRef!$C$2:$C154, $F36 ), SUMIFS( PriceRef!$D$2:$D154, PriceRef!$A$2:$A154, "Suede", PriceRef!$C$2:$C154, $E36 ), SUMIFS( PriceRef!$D$2:$D154, PriceRef!$A$2:$A154, "TwoTone", PriceRef!$C$2:$C154, $G36 ) ) -> 2985 | K36: interior.2 | L36: =textjoin(" ",true,B36,C36,D36,F36,E36,G36) -> 2LT AH2 HU6 N26 TU7
A37: 2LT Colors | B37: 2LT | C37: AE4 | D37: HU7 | E37: N26 | H37: Adrenaline Red Napa with (black) sueded microfiber inserts | I37: AE4 Comp Seats , Includes Suede Steering Wheel. Interior color is on seats, doors, and console trim. | J37: =SUM( SUMIFS( PriceRef!$D$2:$D154, PriceRef!$A$2:$A154, "Seat", PriceRef!$B$2:$B154, $B37, PriceRef!$C$2:$C154, $C37 ), SUMIFS( PriceRef!$D$2:$D154, PriceRef!$A$2:$A154, "Stitching", PriceRef!$C$2:$C154, $F37 ), SUMIFS( PriceRef!$D$2:$D154, PriceRef!$A$2:$A154, "Suede", PriceRef!$C$2:$C154, $E37 ), SUMIFS( PriceRef!$D$2:$D154, PriceRef!$A$2:$A154, "TwoTone", PriceRef!$C$2:$C154, $G37 ) ) -> 2690 | K37: interior.2 | L37: =textjoin(" ",true,B37,C37,D37,F37,E37,G37) -> 2LT AE4 HU7 N26
A38: 2LT Colors | B38: 2LT | C38: AH2 | D38: HU7 | E38: N26 | G38: TU7 | H38: Adrenaline Red Napa with (black) sueded microfiber inserts and two tone seats | I38: AH2 GT2 Seats , Includes Suede Steering Wheel. Interior color is on seats, doors, and console trim. TU7 Two tone seats required | J38: =SUM( SUMIFS( PriceRef!$D$2:$D154, PriceRef!$A$2:$A154, "Seat", PriceRef!$B$2:$B154, $B38, PriceRef!$C$2:$C154, $C38 ), SUMIFS( PriceRef!$D$2:$D154, PriceRef!$A$2:$A154, "Stitching", PriceRef!$C$2:$C154, $F38 ), SUMIFS( PriceRef!$D$2:$D154, PriceRef!$A$2:$A154, "Suede", PriceRef!$C$2:$C154, $E38 ), SUMIFS( PriceRef!$D$2:$D154, PriceRef!$A$2:$A154, "TwoTone", PriceRef!$C$2:$C154, $G38 ) ) -> 2985 | K38: interior.2 | L38: =textjoin(" ",true,B38,C38,D38,F38,E38,G38) -> 2LT AH2 HU7 N26 TU7
A39: 2LT Colors | B39: 2LT | C39: AH2 | D39: HUK | H39: Sky Cool Gray Napa | I39: AH2 GT2 Seats. Interior color is on seats, doors, and console trim. TU7 Two tone seats available with GT2 seats | J39: =SUM( SUMIFS( PriceRef!$D$2:$D154, PriceRef!$A$2:$A154, "Seat", PriceRef!$B$2:$B154, $B39, PriceRef!$C$2:$C154, $C39 ), SUMIFS( PriceRef!$D$2:$D154, PriceRef!$A$2:$A154, "Stitching", PriceRef!$C$2:$C154, $F39 ), SUMIFS( PriceRef!$D$2:$D154, PriceRef!$A$2:$A154, "Suede", PriceRef!$C$2:$C154, $E39 ), SUMIFS( PriceRef!$D$2:$D154, PriceRef!$A$2:$A154, "TwoTone", PriceRef!$C$2:$C154, $G39 ) ) -> 1695 | K39: interior.2 | L39: =textjoin(" ",true,B39,C39,D39,F39,E39,G39) -> 2LT AH2 HUK
A40: 2LT Colors | B40: 2LT | C40: AE4 | D40: HUK | H40: Sky Cool Gray Napa | I40: AE4 Comp Seats are black. Interior color is on seats, doors, and console trim. | J40: =SUM( SUMIFS( PriceRef!$D$2:$D154, PriceRef!$A$2:$A154, "Seat", PriceRef!$B$2:$B154, $B40, PriceRef!$C$2:$C154, $C40 ), SUMIFS( PriceRef!$D$2:$D154, PriceRef!$A$2:$A154, "Stitching", PriceRef!$C$2:$C154, $F40 ), SUMIFS( PriceRef!$D$2:$D154, PriceRef!$A$2:$A154, "Suede", PriceRef!$C$2:$C154, $E40 ), SUMIFS( PriceRef!$D$2:$D154, PriceRef!$A$2:$A154, "TwoTone", PriceRef!$C$2:$C154, $G40 ) ) -> 1995 | K40: interior.2 | L40: =textjoin(" ",true,B40,C40,D40,F40,E40,G40) -> 2LT AE4 HUK
...

Sheet All_S
A1: RPO | B1: Description | C1: MISSING IN STINGRAY | E1: 1LT | F1: 2LT | G1: 3LT | H1: OTHER
A2: 36S | B2: Competition Yellow custom leather stitch | C2: =IFERROR(__xludf.DUMMYFUNCTION("IFERROR( FILTER( A2:B235, ( COUNTIF(STINGRAY!$A$2:$A$133, A2:A235) + COUNTIF(STINGRAY_INT!$D$2:$G$154, A2:A235) ) = 0 ), ""All codes accounted for"" )"),"A2X") -> A2X | D2: =IFERROR(__xludf.DUMMYFUNCTION("""COMPUTED_VALUE"""),"Seat adjuster, driver 8-way power") -> Seat adjuster, driver 8-way power | E2: 1LT | F2: 2LT | G2: 3LT
A3: 379 | B3: Seat belt color, Orange | C3: =IFERROR(__xludf.DUMMYFUNCTION("""COMPUTED_VALUE"""),"A7K") -> A7K | D3: =IFERROR(__xludf.DUMMYFUNCTION("""COMPUTED_VALUE"""),"Seat adjuster, passenger 8-way power") -> Seat adjuster, passenger 8-way power | E3: 1LT | F3: 2LT | G3: 3LT
A4: 37S | B4: Santorini Blue custom leather stitch | C4: =IFERROR(__xludf.DUMMYFUNCTION("""COMPUTED_VALUE"""),"AHE") -> AHE | D4: =IFERROR(__xludf.DUMMYFUNCTION("""COMPUTED_VALUE"""),"Seat adjuster, driver power bolster") -> Seat adjuster, driver power bolster | F4: 2LT | G4: 3LT
A5: 38S | B5: Adrenaline Red custom leather stitch | C5: =IFERROR(__xludf.DUMMYFUNCTION("""COMPUTED_VALUE"""),"AHH") -> AHH | D5: =IFERROR(__xludf.DUMMYFUNCTION("""COMPUTED_VALUE"""),"Seat adjuster, passenger power bolster") -> Seat adjuster, passenger power bolster | G5: 3LT
A6: 3A9 | B6: Seat belt color, Santorini Blue | C6: =IFERROR(__xludf.DUMMYFUNCTION("""COMPUTED_VALUE"""),"AJ7") -> AJ7 | D6: =IFERROR(__xludf.DUMMYFUNCTION("""COMPUTED_VALUE"""),"Airbags, frontal and side-impact, driver and passenger") -> Airbags, frontal and side-impact, driver and passenger | E6: 1LT | F6: 2LT | G6: 3LT
A7: 3F9 | B7: Seat belt color, Torch Red | C7: =IFERROR(__xludf.DUMMYFUNCTION("""COMPUTED_VALUE"""),"AL9") -> AL9 | D7: =IFERROR(__xludf.DUMMYFUNCTION("""COMPUTED_VALUE"""),"Seat adjuster, power driver lumbar control") -> Seat adjuster, power driver lumbar control | F7: 2LT | G7: 3LT
A8: 3M9 | B8: Seat belt color, Yellow | C8: =IFERROR(__xludf.DUMMYFUNCTION("""COMPUTED_VALUE"""),"AP9") -> AP9 | D8: =IFERROR(__xludf.DUMMYFUNCTION("""COMPUTED_VALUE"""),"Cargo nets") -> Cargo nets | F8: 2LT | G8: 3LT
A9: 3N9 | B9: Seat belt color, Natural | C9: =IFERROR(__xludf.DUMMYFUNCTION("""COMPUTED_VALUE"""),"AQA") -> AQA | D9: =IFERROR(__xludf.DUMMYFUNCTION("""COMPUTED_VALUE"""),"Memory Driver and Passenger Convenience Package") -> Memory Driver and Passenger Convenience Package | F9: 2LT | G9: 3LT
A10: 5DG | B10: LPO, 19" x 8.5" (48.3 cm x 21.6 cm) front and 20" x 11" (50.8 cm x 25.4 cm) rear 20-spoke Tech Bronze aluminum wheels | C10: =IFERROR(__xludf.DUMMYFUNCTION("""COMPUTED_VALUE"""),"AT9") -> AT9 | D10: =IFERROR(__xludf.DUMMYFUNCTION("""COMPUTED_VALUE"""),"Seat adjuster, power passenger lumbar control") -> Seat adjuster, power passenger lumbar control | F10: 2LT | G10: 3LT
A11: 5DO | B11: LPO, 19" x 8.5" (48.3 cm x 21.6 cm) front and 20" x 11" (50.8 cm x 25.4 cm) rear 15-spoke bright polished aluminum wheels | C11: =IFERROR(__xludf.DUMMYFUNCTION("""COMPUTED_VALUE"""),"B4Z") -> B4Z | D11: =IFERROR(__xludf.DUMMYFUNCTION("""COMPUTED_VALUE"""),"Performance Traction Management") -> Performance Traction Management | H11: FE4
A12: 5JR | B12: LPO, Outside mirror covers in visible Carbon Fiber | C12: =IFERROR(__xludf.DUMMYFUNCTION("""COMPUTED_VALUE"""),"CFX") -> CFX | D12: =IFERROR(__xludf.DUMMYFUNCTION("""COMPUTED_VALUE"""),"Plaque, personalized with Corvette Museum logo") -> Plaque, personalized with Corvette Museum logo | H12: R8C
A13: 5V7 | B13: LPO, Black Ground Effects | C13: =IFERROR(__xludf.DUMMYFUNCTION("""COMPUTED_VALUE"""),"CJ2") -> CJ2 | D13: =IFERROR(__xludf.DUMMYFUNCTION("""COMPUTED_VALUE"""),"Air conditioning, dual-zone automatic climate control") -> Air conditioning, dual-zone automatic climate control | E13: 1LT | F13: 2LT | G13: 3LT
A14: 5ZC | B14: LPO, Jake logo wheel center caps | C14: =IFERROR(__xludf.DUMMYFUNCTION("""COMPUTED_VALUE"""),"DRG") -> DRG | D14: =IFERROR(__xludf.DUMMYFUNCTION("""COMPUTED_VALUE"""),"Mirrors, outside, Carbon Flash Metallic-painted") -> Mirrors, outside, Carbon Flash Metallic-painted | H14: ZYC, 5JR
A15: 5ZD | B15: LPO, Carbon Flash wheel center caps with crossed flags logo | C15: =IFERROR(__xludf.DUMMYFUNCTION("""COMPUTED_VALUE"""),"DRZ") -> DRZ | D15: =IFERROR(__xludf.DUMMYFUNCTION("""COMPUTED_VALUE"""),"Rear Camera Mirror") -> Rear Camera Mirror | E15: 1 | F15: 2 | G15: 3
A16: 5ZU | B16: LPO, High wing spoiler | C16: =IFERROR(__xludf.DUMMYFUNCTION("""COMPUTED_VALUE"""),"DWK") -> DWK | D16: =IFERROR(__xludf.DUMMYFUNCTION("""COMPUTED_VALUE"""),"Mirrors, outside heated, power-adjustable") -> Mirrors, outside heated, power-adjustable | E16: 1
A17: 5ZW | B17: LPO, Two-Stanchion spoiler, Visible Carbon Fiber | C17: =IFERROR(__xludf.DUMMYFUNCTION("""COMPUTED_VALUE"""),"DYX") -> DYX | D17: =IFERROR(__xludf.DUMMYFUNCTION("""COMPUTED_VALUE"""),"Mirrors, outside heated, power-adjustable") -> Mirrors, outside heated, power-adjustable | F17: 2 | G17: 3
A18: 5ZZ | B18: LPO, High wing spoiler, Carbon Flash Metallic-painted | C18: =IFERROR(__xludf.DUMMYFUNCTION("""COMPUTED_VALUE"""),"FE1") -> FE1 | D18: =IFERROR(__xludf.DUMMYFUNCTION("""COMPUTED_VALUE"""),"Suspension, Corvette standard") -> Suspension, Corvette standard
A19: 719 | B19: Seat belt color, Black | C19: =IFERROR(__xludf.DUMMYFUNCTION("""COMPUTED_VALUE"""),"FE3") -> FE3 | D19: =IFERROR(__xludf.DUMMYFUNCTION("""COMPUTED_VALUE"""),"Suspension, Z51 performance") -> Suspension, Z51 performance
A20: A2X | B20: Seat adjuster, driver 8-way power | C20: =IFERROR(__xludf.DUMMYFUNCTION("""COMPUTED_VALUE"""),"FE9") -> FE9 | D20: =IFERROR(__xludf.DUMMYFUNCTION("""COMPUTED_VALUE"""),"Emissions, Federal requirements") -> Emissions, Federal requirements
A21: A7K | B21: Seat adjuster, passenger 8-way power | C21: =IFERROR(__xludf.DUMMYFUNCTION("""COMPUTED_VALUE"""),"G0J") -> G0J | D21: =IFERROR(__xludf.DUMMYFUNCTION("""COMPUTED_VALUE"""),"Differential, mechanical limited-slip") -> Differential, mechanical limited-slip
A22: AE4 | B22: Seats, Competition Sport bucket | C22: =IFERROR(__xludf.DUMMYFUNCTION("""COMPUTED_VALUE"""),"G96") -> G96 | D22: =IFERROR(__xludf.DUMMYFUNCTION("""COMPUTED_VALUE"""),"Differential, electronic limited-slip") -> Differential, electronic limited-slip
A23: AH2 | B23: Seats, GT2 bucket | C23: =IFERROR(__xludf.DUMMYFUNCTION("""COMPUTED_VALUE"""),"GM7") -> GM7 | D23: =IFERROR(__xludf.DUMMYFUNCTION("""COMPUTED_VALUE"""),"Rear axle, performance ratio") -> Rear axle, performance ratio
A24: AHE | B24: Seat adjuster, driver power bolster | C24: =IFERROR(__xludf.DUMMYFUNCTION("""COMPUTED_VALUE"""),"IVE") -> IVE | D24: =IFERROR(__xludf.DUMMYFUNCTION("""COMPUTED_VALUE"""),"NEW! Infotainment system with Google Built-In") -> NEW! Infotainment system with Google Built-In
A25: AHH | B25: Seat adjuster, passenger power bolster | C25: =IFERROR(__xludf.DUMMYFUNCTION("""COMPUTED_VALUE"""),"IWE") -> IWE | D25: =IFERROR(__xludf.DUMMYFUNCTION("""COMPUTED_VALUE"""),"Sueded Microfiber-Wrapped Upper Interior Trim Package") -> Sueded Microfiber-Wrapped Upper Interior Trim Package
A26: AJ7 | B26: Airbags, frontal and side-impact, driver and passenger | C26: =IFERROR(__xludf.DUMMYFUNCTION("""COMPUTED_VALUE"""),"J55") -> J55 | D26: =IFERROR(__xludf.DUMMYFUNCTION("""COMPUTED_VALUE"""),"Brakes, Z51 performance") -> Brakes, Z51 performance
A27: AL9 | B27: Seat adjuster, power driver lumbar control | C27: =IFERROR(__xludf.DUMMYFUNCTION("""COMPUTED_VALUE"""),"JL9") -> JL9 | D27: =IFERROR(__xludf.DUMMYFUNCTION("""COMPUTED_VALUE"""),"Brakes, 4-wheel antilock, 4-wheel disc") -> Brakes, 4-wheel antilock, 4-wheel disc
A28: AP9 | B28: Cargo nets | C28: =IFERROR(__xludf.DUMMYFUNCTION("""COMPUTED_VALUE"""),"K7A") -> K7A | D28: =IFERROR(__xludf.DUMMYFUNCTION("""COMPUTED_VALUE"""),"NEW! Wireless Phone Charging") -> NEW! Wireless Phone Charging
A29: AQ9 | B29: Seats, GT1 bucket | C29: =IFERROR(__xludf.DUMMYFUNCTION("""COMPUTED_VALUE"""),"K7B") -> K7B | D29: =IFERROR(__xludf.DUMMYFUNCTION("""COMPUTED_VALUE"""),"NEW! Wireless Phone Charging") -> NEW! Wireless Phone Charging
A30: AQA | B30: Memory Driver and Passenger Convenience Package | C30: =IFERROR(__xludf.DUMMYFUNCTION("""COMPUTED_VALUE"""),"KI3") -> KI3 | D30: =IFERROR(__xludf.DUMMYFUNCTION("""COMPUTED_VALUE"""),"Steering wheel, heated") -> Steering wheel, heated
A31: AT9 | B31: Seat adjuster, power passenger lumbar control | C31: =IFERROR(__xludf.DUMMYFUNCTION("""COMPUTED_VALUE"""),"KQV") -> KQV | D31: =IFERROR(__xludf.DUMMYFUNCTION("""COMPUTED_VALUE"""),"Seats, heated and vented driver and passenger") -> Seats, heated and vented driver and passenger
A32: AUP | B32: NEW! Seats, mixed, driver Competition Sport bucket, passenger GT2 bucket | C32: =IFERROR(__xludf.DUMMYFUNCTION("""COMPUTED_VALUE"""),"LT2") -> LT2 | D32: =IFERROR(__xludf.DUMMYFUNCTION("""COMPUTED_VALUE"""),"Engine, 6.2L V8 DI") -> Engine, 6.2L V8 DI
A33: B4Z | B33: Performance Traction Management | C33: =IFERROR(__xludf.DUMMYFUNCTION("""COMPUTED_VALUE"""),"M1L") -> M1L | D33: =IFERROR(__xludf.DUMMYFUNCTION("""COMPUTED_VALUE"""),"Transmission, 8-speed dual clutch") -> Transmission, 8-speed dual clutch
A34: B6P | B34: Coupe Engine Appearance Package | C34: =IFERROR(__xludf.DUMMYFUNCTION("""COMPUTED_VALUE"""),"N38") -> N38 | D34: =IFERROR(__xludf.DUMMYFUNCTION("""COMPUTED_VALUE"""),"Steering column, power tilt and telescopic") -> Steering column, power tilt and telescopic
A35: BAZ | B35: Stealth Interior Trim Package | C35: =IFERROR(__xludf.DUMMYFUNCTION("""COMPUTED_VALUE"""),"NB8") -> NB8 | D35: =IFERROR(__xludf.DUMMYFUNCTION("""COMPUTED_VALUE"""),"Emissions override, California ") -> Emissions override, California
A36: BC7 | B36: LT2 engine cover | C36: =IFERROR(__xludf.DUMMYFUNCTION("""COMPUTED_VALUE"""),"NB9") -> NB9 | D36: =IFERROR(__xludf.DUMMYFUNCTION("""COMPUTED_VALUE"""),"Emissions override, state-specific") -> Emissions override, state-specific
A37: BCP | B37: LT2 engine cover | C37: =IFERROR(__xludf.DUMMYFUNCTION("""COMPUTED_VALUE"""),"NC7") -> NC7 | D37: =IFERROR(__xludf.DUMMYFUNCTION("""COMPUTED_VALUE"""),"Emissions override, Federal") -> Emissions override, Federal
A38: BCS | B38: LT2 engine cover | C38: =IFERROR(__xludf.DUMMYFUNCTION("""COMPUTED_VALUE"""),"NE1") -> NE1 | D38: =IFERROR(__xludf.DUMMYFUNCTION("""COMPUTED_VALUE"""),"Emissions") -> Emissions
A39: BV4 | B39: Plaque, personalized | C39: =IFERROR(__xludf.DUMMYFUNCTION("""COMPUTED_VALUE"""),"NK4") -> NK4 | D39: =IFERROR(__xludf.DUMMYFUNCTION("""COMPUTED_VALUE"""),"Steering wheel, leather-wrapped") -> Steering wheel, leather-wrapped
A40: C2Z | B40: Roof panel, visible carbon fiber with body-color surround | C40: =IFERROR(__xludf.DUMMYFUNCTION("""COMPUTED_VALUE"""),"P0H") -> P0H | D40: =IFERROR(__xludf.DUMMYFUNCTION("""COMPUTED_VALUE"""),"12 Months OnStar Connect Plus") -> 12 Months OnStar Connect Plus
...

Sheet ERAY
A1: RPO Code | B1: Name | C1: Price | D1: Detail | E1: Compatibility | F1: Category | G1: Section
A2: EFR | B2: Carbon Flash exterior accents | C2: 0 | D2: Standard Carbon Flash. Includes side vents and front/rear grille accents. Includes tonneau vent on convertible. Includes rockers on E-Ray and Z06 | F2: accents | G2: Accents
A3: EFY-e | B3: Body Color exterior accents | C3: 0 | D3: Standard. Includes side vents, rockers, and front/rear grille accents. Includes tonneau vent on convertible. | F3: accents | G3: Accents
A4: EYK | B4: Chrome Exterior Badge Package | C4: 295 | D4: Includes badges on the nose and decklid, "Corvette" script on rear, and lower rocker badge on wide-body models. | F4: badges | G4: Badges
A5: EYT | B5: Carbon Flash Exterior Badge Package | C5: 0 | D5: Standard. Includes badges on the nose and decklid, "Corvette" script on rear, and lower rocker badge on wide-body models. | F5: badges | G5: Badges
A6: J6B | B6: Blue Painted Calipers | C6: 695 | D6: Requires J57 Ceramic brakes | E6: Requires J57 Ceramic brakes | F6: calipers | G6: Brake Calipers
A7: J6D | B7: Dark Gray metallic Painted Calipers | C7: 0 | D7: Standard with J57, Requires J57 Ceramic brakes | E7: Requires J57 Ceramic brakes | F7: calipers | G7: Brake Calipers
A8: J6E | B8: Velocity Yellow Painted Calipers | C8: 695 | D8: Gloss finish | F8: calipers | G8: Brake Calipers
A9: J6F | B9: Bright Red Painted Calipers | C9: 695 | D9: Gloss finish | F9: calipers | G9: Brake Calipers
A10: J6L | B10: Orange Painted Calipers | C10: 695 | D10: Requires J57 Ceramic brakes | E10: Requires J57 Ceramic brakes | F10: calipers | G10: Brake Calipers
A11: J6N | B11: Edge Red Painted Calipers | C11: 695 | D11: Darker shade of red, satin finish | F11: calipers | G11: Brake Calipers
A12: RWH | B12: Premium Indoor car cover, Black with crossed flags logo | C12: 495 | F12: lpo | G12: Car Covers
A13: RWJ | B13: LPO, Premium outdoor car cover, Gray with crossed flags logo and Corvette silhouette | C13: 495 | F13: lpo | G13: Car Covers
A14: WKR | B14: NEW! LPO, Premium indoor car cover, GT3.R, fully rendered | C14: 495 | F14: lpo | G14: Car Covers
A15: 5JR | B15: Visible Carbon Fiber Mirror Covers | C15: 1250 | D15: 3LT/LZ only. Adds DRG carbon flash painted mirrors (N/C) | E15: 3LT/LZ only. Available with 1LZ on ZR1. | F15: carbon_fiber, lpo | G15: Carbon Fiber
A16: CFV | B16: Carbon Fiber Ground Effects- Visible Carbon weave | C16: 3995 | D16: Included with T0G | F16: carbon_fiber, lpo | G16: Carbon Fiber
A17: CFZ | B17: Carbon Fiber Ground Effects- Carbon Flash metallic Painted | C17: 2995 | D17: Included with T0F | F17: carbon_fiber, lpo | G17: Carbon Fiber
A18: SLN | B18: Visible Carbon Fiber Engine Cross Brace w/ Jake Logo | C18: 2895 | D18: Not available with RXI | E18: Not available with RXI | F18: carbon_fiber, engine_bay, lpo | G18: Carbon Fiber
A19: V8X | B19: Visible Carbon Fiber Sill Plates | C19: 1995 | D19: Corvette Script and sillhouette logo | F19: carbon_fiber, lpo | G19: Carbon Fiber
A20: CM9 | B20: Body-Color roof and nacelles | C20: 0 | D20: Standard | F20: roof | G20: Convertible Roof Panel
A21: D84 | B21: Carbon Flash painted nacelles and roof | C21: 1295 | D21: Not available w/ GBA Black | E21: Not available w/ GBA Black | F21: roof | G21: Convertible Roof Panel
